MotChallenge2DBox
MPNTrack
Traceback (most recent call last):
  File "C:\Users\Salva\Downloads\TrackEval\trackeval\eval.py", line 126, in evaluate
    output_fol = dataset.get_output_fol(tracker)
  File "C:\Users\Salva\Downloads\TrackEval\trackeval\datasets\_base_dataset.py", line 54, in get_output_fol
    return os.path.join(self.output_fol, tracker, self.output_sub_fol)
  File "C:\Users\Salva\anaconda3\lib\ntpath.py", line 76, in join
    path = os.fspath(path)
TypeError: expected str, bytes or os.PathLike object, not list





MotChallenge2DBox
MPNTrack
Traceback (most recent call last):
  File "C:\Users\Salva\Downloads\TrackEval\trackeval\eval.py", line 126, in evaluate
    output_fol = dataset.get_output_fol(tracker)
  File "C:\Users\Salva\Downloads\TrackEval\trackeval\datasets\_base_dataset.py", line 54, in get_output_fol
    return os.path.join(self.output_fol, tracker, self.output_sub_fol)
  File "C:\Users\Salva\anaconda3\lib\ntpath.py", line 76, in join
    path = os.fspath(path)
TypeError: expected str, bytes or os.PathLike object, not list





MotChallenge2DBox
MPNTrack
Traceback (most recent call last):
  File "C:\Users\Salva\Downloads\TrackEval\trackeval\eval.py", line 126, in evaluate
    output_fol = dataset.get_output_fol(tracker)
  File "C:\Users\Salva\Downloads\TrackEval\trackeval\datasets\_base_dataset.py", line 54, in get_output_fol
    return os.path.join(self.output_fol, tracker, self.output_sub_fol)
  File "C:\Users\Salva\anaconda3\lib\ntpath.py", line 76, in join
    path = os.fspath(path)
TypeError: expected str, bytes or os.PathLike object, not list





MotChallenge2DBox
data
Traceback (most recent call last):
  File "C:\Users\caros\Documents\Projects\proyecto-final\TrackEval\trackeval\eval.py", line 86, in evaluate
    res[curr_seq] = eval_sequence(curr_seq, dataset, tracker, class_list, metrics_list,
  File "C:\Users\caros\Documents\Projects\proyecto-final\TrackEval\trackeval\_timing.py", line 17, in wrap
    result = f(*args, **kw)
  File "C:\Users\caros\Documents\Projects\proyecto-final\TrackEval\trackeval\eval.py", line 195, in eval_sequence
    data = dataset.get_preprocessed_seq_data(raw_data, cls)
  File "C:\Users\caros\Documents\Projects\proyecto-final\TrackEval\trackeval\_timing.py", line 17, in wrap
    result = f(*args, **kw)
  File "C:\Users\caros\Documents\Projects\proyecto-final\TrackEval\trackeval\datasets\mot_challenge_2d_box.py", line 323, in get_preprocessed_seq_data
    self._check_unique_ids(raw_data)
  File "C:\Users\caros\Documents\Projects\proyecto-final\TrackEval\trackeval\datasets\_base_dataset.py", line 315, in _check_unique_ids
    raise TrackEvalException(exc_str)
trackeval.utils.TrackEvalException: Tracker predicts the same ID more than once in a single timestep (seq: PF-01, frame: 1, ids: 2 5)





