MotChallenge2DBox
data
Traceback (most recent call last):
  File "C:\Users\caros\Documents\Projects\proyecto-final\TrackEval\trackeval\eval.py", line 86, in evaluate
    res[curr_seq] = eval_sequence(curr_seq, dataset, tracker, class_list, metrics_list,
  File "C:\Users\caros\Documents\Projects\proyecto-final\TrackEval\trackeval\_timing.py", line 17, in wrap
    result = f(*args, **kw)
  File "C:\Users\caros\Documents\Projects\proyecto-final\TrackEval\trackeval\eval.py", line 195, in eval_sequence
    data = dataset.get_preprocessed_seq_data(raw_data, cls)
  File "C:\Users\caros\Documents\Projects\proyecto-final\TrackEval\trackeval\_timing.py", line 17, in wrap
    result = f(*args, **kw)
  File "C:\Users\caros\Documents\Projects\proyecto-final\TrackEval\trackeval\datasets\mot_challenge_2d_box.py", line 323, in get_preprocessed_seq_data
    self._check_unique_ids(raw_data)
  File "C:\Users\caros\Documents\Projects\proyecto-final\TrackEval\trackeval\datasets\_base_dataset.py", line 315, in _check_unique_ids
    raise TrackEvalException(exc_str)
trackeval.utils.TrackEvalException: Tracker predicts the same ID more than once in a single timestep (seq: PF-01, frame: 413, ids: 85)





MotChallenge2DBox
data
Traceback (most recent call last):
  File "C:\Users\caros\Documents\Projects\proyecto-final\TrackEval\trackeval\eval.py", line 86, in evaluate
    res[curr_seq] = eval_sequence(curr_seq, dataset, tracker, class_list, metrics_list,
  File "C:\Users\caros\Documents\Projects\proyecto-final\TrackEval\trackeval\_timing.py", line 17, in wrap
    result = f(*args, **kw)
  File "C:\Users\caros\Documents\Projects\proyecto-final\TrackEval\trackeval\eval.py", line 195, in eval_sequence
    data = dataset.get_preprocessed_seq_data(raw_data, cls)
  File "C:\Users\caros\Documents\Projects\proyecto-final\TrackEval\trackeval\_timing.py", line 17, in wrap
    result = f(*args, **kw)
  File "C:\Users\caros\Documents\Projects\proyecto-final\TrackEval\trackeval\datasets\mot_challenge_2d_box.py", line 323, in get_preprocessed_seq_data
    self._check_unique_ids(raw_data)
  File "C:\Users\caros\Documents\Projects\proyecto-final\TrackEval\trackeval\datasets\_base_dataset.py", line 315, in _check_unique_ids
    raise TrackEvalException(exc_str)
trackeval.utils.TrackEvalException: Tracker predicts the same ID more than once in a single timestep (seq: PF-01, frame: 413, ids: 85)





